[2025-05-06T15:20:23.608+0000] {local_task_job_runner.py:120} INFO - ::group::Pre task execution logs
[2025-05-06T15:20:23.635+0000] {taskinstance.py:2076} INFO - Dependencies all met for dep_context=non-requeueable deps ti=<TaskInstance: weather_etl_dag.run-dbt manual__2025-05-06T15:20:20.184606+00:00 [queued]>
[2025-05-06T15:20:23.644+0000] {taskinstance.py:2076} INFO - Dependencies all met for dep_context=requeueable deps ti=<TaskInstance: weather_etl_dag.run-dbt manual__2025-05-06T15:20:20.184606+00:00 [queued]>
[2025-05-06T15:20:23.645+0000] {taskinstance.py:2306} INFO - Starting attempt 1 of 1
[2025-05-06T15:20:23.655+0000] {taskinstance.py:2330} INFO - Executing <Task(PythonOperator): run-dbt> on 2025-05-06 15:20:20.184606+00:00
[2025-05-06T15:20:23.666+0000] {standard_task_runner.py:90} INFO - Running: ['airflow', 'tasks', 'run', 'weather_etl_dag', 'run-dbt', 'manual__2025-05-06T15:20:20.184606+00:00', '--job-id', '50', '--raw', '--subdir', 'DAGS_FOLDER/weather_etl_dag.py', '--cfg-path', '/tmp/tmpujqdz3f3']
[2025-05-06T15:20:23.669+0000] {standard_task_runner.py:91} INFO - Job 50: Subtask run-dbt
[2025-05-06T15:20:23.675+0000] {logging_mixin.py:188} WARNING - /home/airflow/.local/lib/python3.12/site-packages/airflow/task/task_runner/standard_task_runner.py:61 DeprecationWarning: This process (pid=6377) is multi-threaded, use of fork() may lead to deadlocks in the child.
[2025-05-06T15:20:23.675+0000] {standard_task_runner.py:63} INFO - Started process 6379 to run task
[2025-05-06T15:20:23.686+0000] {logging_mixin.py:188} WARNING - /home/airflow/.local/lib/python3.12/site-packages/airflow/settings.py:195 DeprecationWarning: The sql_alchemy_conn option in [core] has been moved to the sql_alchemy_conn option in [database] - the old setting has been used, but please update your config.
[2025-05-06T15:20:23.722+0000] {task_command.py:426} INFO - Running <TaskInstance: weather_etl_dag.run-dbt manual__2025-05-06T15:20:20.184606+00:00 [running]> on host 1259ec087e8d
[2025-05-06T15:20:23.803+0000] {taskinstance.py:2648} INFO - Exporting env vars: AIRFLOW_CTX_DAG_OWNER='airflow' AIRFLOW_CTX_DAG_ID='weather_etl_dag' AIRFLOW_CTX_TASK_ID='run-dbt' AIRFLOW_CTX_EXECUTION_DATE='2025-05-06T15:20:20.184606+00:00' AIRFLOW_CTX_TRY_NUMBER='1' AIRFLOW_CTX_DAG_RUN_ID='manual__2025-05-06T15:20:20.184606+00:00'
[2025-05-06T15:20:23.804+0000] {taskinstance.py:430} INFO - ::endgroup::
[2025-05-06T15:20:23.949+0000] {taskinstance.py:441} INFO - ::group::Post task execution logs
[2025-05-06T15:20:23.950+0000] {taskinstance.py:2905} ERROR - Task failed with exception
Traceback (most recent call last):
  File "/home/airflow/.local/lib/python3.12/site-packages/airflow/models/taskinstance.py", line 465, in _execute_task
    result = _execute_callable(context=context, **execute_callable_kwargs)
             ^^^^^^^^^^^^^^^^^^^^^^^^^^^^^^^^^^^^^^^^^^^^^^^^^^^^^^^^^^^^^
  File "/home/airflow/.local/lib/python3.12/site-packages/airflow/models/taskinstance.py", line 432, in _execute_callable
    return execute_callable(context=context, **execute_callable_kwargs)
           ^^^^^^^^^^^^^^^^^^^^^^^^^^^^^^^^^^^^^^^^^^^^^^^^^^^^^^^^^^^^
  File "/home/airflow/.local/lib/python3.12/site-packages/airflow/models/baseoperator.py", line 400, in wrapper
    return func(self, *args, **kwargs)
           ^^^^^^^^^^^^^^^^^^^^^^^^^^^
  File "/home/airflow/.local/lib/python3.12/site-packages/airflow/operators/python.py", line 235, in execute
    return_value = self.execute_callable()
                   ^^^^^^^^^^^^^^^^^^^^^^^
  File "/home/airflow/.local/lib/python3.12/site-packages/airflow/operators/python.py", line 252, in execute_callable
    return self.python_callable(*self.op_args, **self.op_kwargs)
           ^^^^^^^^^^^^^^^^^^^^^^^^^^^^^^^^^^^^^^^^^^^^^^^^^^^^^
  File "/opt/airflow/dags/weather_etl_dag.py", line 9, in run_dbt
    subprocess.run(['dbt', 'run'], check=True, cwd='/opt/airflow/weather_project')
  File "/usr/local/lib/python3.12/subprocess.py", line 548, in run
    with Popen(*popenargs, **kwargs) as process:
         ^^^^^^^^^^^^^^^^^^^^^^^^^^^
  File "/usr/local/lib/python3.12/subprocess.py", line 1026, in __init__
    self._execute_child(args, executable, preexec_fn, close_fds,
  File "/usr/local/lib/python3.12/subprocess.py", line 1955, in _execute_child
    raise child_exception_type(errno_num, err_msg, err_filename)
FileNotFoundError: [Errno 2] No such file or directory: '/opt/airflow/weather_project'
[2025-05-06T15:20:23.971+0000] {taskinstance.py:1206} INFO - Marking task as FAILED. dag_id=weather_etl_dag, task_id=run-dbt, run_id=manual__2025-05-06T15:20:20.184606+00:00, execution_date=20250506T152020, start_date=20250506T152023, end_date=20250506T152023
[2025-05-06T15:20:23.982+0000] {standard_task_runner.py:110} ERROR - Failed to execute job 50 for task run-dbt ([Errno 2] No such file or directory: '/opt/airflow/weather_project'; 6379)
[2025-05-06T15:20:24.010+0000] {local_task_job_runner.py:240} INFO - Task exited with return code 1
[2025-05-06T15:20:24.031+0000] {taskinstance.py:3498} INFO - 0 downstream tasks scheduled from follow-on schedule check
[2025-05-06T15:20:24.034+0000] {local_task_job_runner.py:222} INFO - ::endgroup::
