[2025-05-06T20:16:20.567+0000] {local_task_job_runner.py:120} INFO - ::group::Pre task execution logs
[2025-05-06T20:16:20.593+0000] {taskinstance.py:2076} INFO - Dependencies all met for dep_context=non-requeueable deps ti=<TaskInstance: weather_etl_dag.run_dbt manual__2025-05-06T20:16:17.419022+00:00 [queued]>
[2025-05-06T20:16:20.601+0000] {taskinstance.py:2076} INFO - Dependencies all met for dep_context=requeueable deps ti=<TaskInstance: weather_etl_dag.run_dbt manual__2025-05-06T20:16:17.419022+00:00 [queued]>
[2025-05-06T20:16:20.603+0000] {taskinstance.py:2306} INFO - Starting attempt 1 of 1
[2025-05-06T20:16:20.615+0000] {taskinstance.py:2330} INFO - Executing <Task(PythonOperator): run_dbt> on 2025-05-06 20:16:17.419022+00:00
[2025-05-06T20:16:20.625+0000] {standard_task_runner.py:90} INFO - Running: ['airflow', 'tasks', 'run', 'weather_etl_dag', 'run_dbt', 'manual__2025-05-06T20:16:17.419022+00:00', '--job-id', '101', '--raw', '--subdir', 'DAGS_FOLDER/weather_etl_dag.py', '--cfg-path', '/tmp/tmpmdymgd42']
[2025-05-06T20:16:20.626+0000] {logging_mixin.py:188} WARNING - /home/airflow/.local/lib/python3.12/site-packages/airflow/task/task_runner/standard_task_runner.py:61 DeprecationWarning: This process (pid=841) is multi-threaded, use of fork() may lead to deadlocks in the child.
[2025-05-06T20:16:20.627+0000] {standard_task_runner.py:91} INFO - Job 101: Subtask run_dbt
[2025-05-06T20:16:20.628+0000] {standard_task_runner.py:63} INFO - Started process 843 to run task
[2025-05-06T20:16:20.643+0000] {logging_mixin.py:188} WARNING - /home/airflow/.local/lib/python3.12/site-packages/airflow/settings.py:195 DeprecationWarning: The sql_alchemy_conn option in [core] has been moved to the sql_alchemy_conn option in [database] - the old setting has been used, but please update your config.
[2025-05-06T20:16:20.678+0000] {task_command.py:426} INFO - Running <TaskInstance: weather_etl_dag.run_dbt manual__2025-05-06T20:16:17.419022+00:00 [running]> on host c6817411f6c2
[2025-05-06T20:16:20.778+0000] {taskinstance.py:2648} INFO - Exporting env vars: AIRFLOW_CTX_DAG_OWNER='airflow' AIRFLOW_CTX_DAG_ID='weather_etl_dag' AIRFLOW_CTX_TASK_ID='run_dbt' AIRFLOW_CTX_EXECUTION_DATE='2025-05-06T20:16:17.419022+00:00' AIRFLOW_CTX_TRY_NUMBER='1' AIRFLOW_CTX_DAG_RUN_ID='manual__2025-05-06T20:16:17.419022+00:00'
[2025-05-06T20:16:20.780+0000] {taskinstance.py:430} INFO - ::endgroup::
[2025-05-06T20:16:25.717+0000] {weather_etl_dag.py:20} ERROR - dbt run failed:

[2025-05-06T20:16:25.718+0000] {taskinstance.py:441} INFO - ::group::Post task execution logs
[2025-05-06T20:16:25.719+0000] {taskinstance.py:2905} ERROR - Task failed with exception
Traceback (most recent call last):
  File "/home/airflow/.local/lib/python3.12/site-packages/airflow/models/taskinstance.py", line 465, in _execute_task
    result = _execute_callable(context=context, **execute_callable_kwargs)
             ^^^^^^^^^^^^^^^^^^^^^^^^^^^^^^^^^^^^^^^^^^^^^^^^^^^^^^^^^^^^^
  File "/home/airflow/.local/lib/python3.12/site-packages/airflow/models/taskinstance.py", line 432, in _execute_callable
    return execute_callable(context=context, **execute_callable_kwargs)
           ^^^^^^^^^^^^^^^^^^^^^^^^^^^^^^^^^^^^^^^^^^^^^^^^^^^^^^^^^^^^
  File "/home/airflow/.local/lib/python3.12/site-packages/airflow/models/baseoperator.py", line 400, in wrapper
    return func(self, *args, **kwargs)
           ^^^^^^^^^^^^^^^^^^^^^^^^^^^
  File "/home/airflow/.local/lib/python3.12/site-packages/airflow/operators/python.py", line 235, in execute
    return_value = self.execute_callable()
                   ^^^^^^^^^^^^^^^^^^^^^^^
  File "/home/airflow/.local/lib/python3.12/site-packages/airflow/operators/python.py", line 252, in execute_callable
    return self.python_callable(*self.op_args, **self.op_kwargs)
           ^^^^^^^^^^^^^^^^^^^^^^^^^^^^^^^^^^^^^^^^^^^^^^^^^^^^^
  File "/opt/airflow/dags/weather_etl_dag.py", line 11, in run_dbt
    result = subprocess.run(
             ^^^^^^^^^^^^^^^
  File "/usr/local/lib/python3.12/subprocess.py", line 571, in run
    raise CalledProcessError(retcode, process.args,
subprocess.CalledProcessError: Command '['dbt', 'run']' returned non-zero exit status 1.
[2025-05-06T20:16:25.742+0000] {taskinstance.py:1206} INFO - Marking task as FAILED. dag_id=weather_etl_dag, task_id=run_dbt, run_id=manual__2025-05-06T20:16:17.419022+00:00, execution_date=20250506T201617, start_date=20250506T201620, end_date=20250506T201625
[2025-05-06T20:16:25.758+0000] {standard_task_runner.py:110} ERROR - Failed to execute job 101 for task run_dbt (Command '['dbt', 'run']' returned non-zero exit status 1.; 843)
[2025-05-06T20:16:25.790+0000] {local_task_job_runner.py:240} INFO - Task exited with return code 1
[2025-05-06T20:16:25.808+0000] {taskinstance.py:3498} INFO - 0 downstream tasks scheduled from follow-on schedule check
[2025-05-06T20:16:25.811+0000] {local_task_job_runner.py:222} INFO - ::endgroup::
