[2025-05-07T03:43:48.895+0000] {local_task_job_runner.py:120} INFO - ::group::Pre task execution logs
[2025-05-07T03:43:48.942+0000] {taskinstance.py:2076} INFO - Dependencies all met for dep_context=non-requeueable deps ti=<TaskInstance: weather_etl_dag.fetch_weather manual__2025-05-07T03:43:46.934121+00:00 [queued]>
[2025-05-07T03:43:48.957+0000] {taskinstance.py:2076} INFO - Dependencies all met for dep_context=requeueable deps ti=<TaskInstance: weather_etl_dag.fetch_weather manual__2025-05-07T03:43:46.934121+00:00 [queued]>
[2025-05-07T03:43:48.958+0000] {taskinstance.py:2306} INFO - Starting attempt 1 of 1
[2025-05-07T03:43:48.977+0000] {taskinstance.py:2330} INFO - Executing <Task(PythonOperator): fetch_weather> on 2025-05-07 03:43:46.934121+00:00
[2025-05-07T03:43:48.992+0000] {logging_mixin.py:188} WARNING - /home/airflow/.local/lib/python3.12/site-packages/airflow/task/task_runner/standard_task_runner.py:61 DeprecationWarning: This process (pid=413) is multi-threaded, use of fork() may lead to deadlocks in the child.
[2025-05-07T03:43:48.990+0000] {standard_task_runner.py:90} INFO - Running: ['airflow', 'tasks', 'run', 'weather_etl_dag', 'fetch_weather', 'manual__2025-05-07T03:43:46.934121+00:00', '--job-id', '158', '--raw', '--subdir', 'DAGS_FOLDER/weather_etl_dag.py', '--cfg-path', '/tmp/tmp_c2_xib2']
[2025-05-07T03:43:48.994+0000] {standard_task_runner.py:63} INFO - Started process 415 to run task
[2025-05-07T03:43:48.994+0000] {standard_task_runner.py:91} INFO - Job 158: Subtask fetch_weather
[2025-05-07T03:43:49.025+0000] {logging_mixin.py:188} WARNING - /home/airflow/.local/lib/python3.12/site-packages/airflow/settings.py:195 DeprecationWarning: The sql_alchemy_conn option in [core] has been moved to the sql_alchemy_conn option in [database] - the old setting has been used, but please update your config.
[2025-05-07T03:43:49.080+0000] {task_command.py:426} INFO - Running <TaskInstance: weather_etl_dag.fetch_weather manual__2025-05-07T03:43:46.934121+00:00 [running]> on host 5e7ac55cd0dc
[2025-05-07T03:43:49.227+0000] {taskinstance.py:2648} INFO - Exporting env vars: AIRFLOW_CTX_DAG_OWNER='airflow' AIRFLOW_CTX_DAG_ID='weather_etl_dag' AIRFLOW_CTX_TASK_ID='fetch_weather' AIRFLOW_CTX_EXECUTION_DATE='2025-05-07T03:43:46.934121+00:00' AIRFLOW_CTX_TRY_NUMBER='1' AIRFLOW_CTX_DAG_RUN_ID='manual__2025-05-07T03:43:46.934121+00:00'
[2025-05-07T03:43:49.229+0000] {taskinstance.py:430} INFO - ::endgroup::
[2025-05-07T03:43:49.984+0000] {logging_mixin.py:188} INFO - Unexpected error: (psycopg2.errors.UndefinedColumn) column "city" of relation "stg_weather_raw" does not exist
LINE 1: INSERT INTO stg_weather_raw (city, country, latitude, longit...
                                     ^

[SQL: INSERT INTO stg_weather_raw (city, country, latitude, longitude, date_time, temperature, pressure, humidity, weather_main, weather_description) VALUES (%(city)s, %(country)s, %(latitude)s, %(longitude)s, %(date_time)s, %(temperature)s, %(pressure)s, %(humidity)s, %(weather_main)s, %(weather_description)s)]
[parameters: {'city': 'Aarhus', 'country': 'DK', 'latitude': 56.1567, 'longitude': 10.2108, 'date_time': '2025-05-07T03:40:12', 'temperature': 3.25, 'pressure': 1022, 'humidity': 89, 'weather_main': 'Clouds', 'weather_description': 'broken clouds'}]
(Background on this error at: https://sqlalche.me/e/14/f405)
[2025-05-07T03:43:49.985+0000] {python.py:237} INFO - Done. Returned value was: None
[2025-05-07T03:43:49.986+0000] {taskinstance.py:441} INFO - ::group::Post task execution logs
[2025-05-07T03:43:50.011+0000] {taskinstance.py:1206} INFO - Marking task as SUCCESS. dag_id=weather_etl_dag, task_id=fetch_weather, run_id=manual__2025-05-07T03:43:46.934121+00:00, execution_date=20250507T034346, start_date=20250507T034348, end_date=20250507T034350
[2025-05-07T03:43:50.055+0000] {local_task_job_runner.py:240} INFO - Task exited with return code 0
[2025-05-07T03:43:50.082+0000] {local_task_job_runner.py:222} INFO - ::endgroup::
