[2025-05-06T20:20:58.040+0000] {local_task_job_runner.py:120} INFO - ::group::Pre task execution logs
[2025-05-06T20:20:58.074+0000] {taskinstance.py:2076} INFO - Dependencies all met for dep_context=non-requeueable deps ti=<TaskInstance: weather_etl_dag.run_dbt manual__2025-05-06T20:20:53.893497+00:00 [queued]>
[2025-05-06T20:20:58.089+0000] {taskinstance.py:2076} INFO - Dependencies all met for dep_context=requeueable deps ti=<TaskInstance: weather_etl_dag.run_dbt manual__2025-05-06T20:20:53.893497+00:00 [queued]>
[2025-05-06T20:20:58.090+0000] {taskinstance.py:2306} INFO - Starting attempt 1 of 1
[2025-05-06T20:20:58.110+0000] {taskinstance.py:2330} INFO - Executing <Task(PythonOperator): run_dbt> on 2025-05-06 20:20:53.893497+00:00
[2025-05-06T20:20:58.127+0000] {logging_mixin.py:188} WARNING - /home/airflow/.local/lib/python3.12/site-packages/airflow/task/task_runner/standard_task_runner.py:61 DeprecationWarning: This process (pid=1015) is multi-threaded, use of fork() may lead to deadlocks in the child.
[2025-05-06T20:20:58.129+0000] {standard_task_runner.py:63} INFO - Started process 1017 to run task
[2025-05-06T20:20:58.127+0000] {standard_task_runner.py:90} INFO - Running: ['airflow', 'tasks', 'run', 'weather_etl_dag', 'run_dbt', 'manual__2025-05-06T20:20:53.893497+00:00', '--job-id', '103', '--raw', '--subdir', 'DAGS_FOLDER/weather_etl_dag.py', '--cfg-path', '/tmp/tmptkga5j13']
[2025-05-06T20:20:58.130+0000] {standard_task_runner.py:91} INFO - Job 103: Subtask run_dbt
[2025-05-06T20:20:58.149+0000] {logging_mixin.py:188} WARNING - /home/airflow/.local/lib/python3.12/site-packages/airflow/settings.py:195 DeprecationWarning: The sql_alchemy_conn option in [core] has been moved to the sql_alchemy_conn option in [database] - the old setting has been used, but please update your config.
[2025-05-06T20:20:58.190+0000] {task_command.py:426} INFO - Running <TaskInstance: weather_etl_dag.run_dbt manual__2025-05-06T20:20:53.893497+00:00 [running]> on host c6817411f6c2
[2025-05-06T20:20:58.294+0000] {taskinstance.py:2648} INFO - Exporting env vars: AIRFLOW_CTX_DAG_OWNER='airflow' AIRFLOW_CTX_DAG_ID='weather_etl_dag' AIRFLOW_CTX_TASK_ID='run_dbt' AIRFLOW_CTX_EXECUTION_DATE='2025-05-06T20:20:53.893497+00:00' AIRFLOW_CTX_TRY_NUMBER='1' AIRFLOW_CTX_DAG_RUN_ID='manual__2025-05-06T20:20:53.893497+00:00'
[2025-05-06T20:20:58.295+0000] {taskinstance.py:430} INFO - ::endgroup::
[2025-05-06T20:21:05.610+0000] {weather_etl_dag.py:19} ERROR - dbt run failed with return code 1
[2025-05-06T20:21:05.611+0000] {weather_etl_dag.py:20} ERROR - stdout:
[0m20:21:02  Running with dbt=1.9.4
[0m20:21:02  Registered adapter: ***=1.9.0
[0m20:21:03  [[33mWARNING[0m]: Configuration paths exist in your dbt_project.yml file which do not apply to any resources.
There are 2 unused configuration paths:
- models.weather_project.staging
- models.weather_project.marts
[0m20:21:03  Found 5 models, 1 test, 433 macros
[0m20:21:03  
[0m20:21:03  Concurrency: 1 threads (target='dev')
[0m20:21:03  
[0m20:21:03  1 of 5 START sql view model public.stg_weather_raw ............................. [RUN]
[0m20:21:04  1 of 5 OK created sql view model public.stg_weather_raw ........................ [[32mCREATE VIEW[0m in 0.23s]
[0m20:21:04  2 of 5 START sql view model public.dim_date .................................... [RUN]
[0m20:21:04  2 of 5 ERROR creating sql view model public.dim_date ........................... [[31mERROR[0m in 0.11s]
[0m20:21:04  3 of 5 START sql view model public.dim_location ................................ [RUN]
[0m20:21:04  3 of 5 ERROR creating sql view model public.dim_location ....................... [[31mERROR[0m in 0.11s]
[0m20:21:04  4 of 5 START sql view model public.dim_weather_condition ....................... [RUN]
[0m20:21:04  4 of 5 ERROR creating sql view model public.dim_weather_condition .............. [[31mERROR[0m in 0.12s]
[0m20:21:04  5 of 5 SKIP relation public.fact_weather ....................................... [[33mSKIP[0m]
[0m20:21:04  
[0m20:21:04  Finished running 5 view models in 0 hours 0 minutes and 1.28 seconds (1.28s).
[0m20:21:04  
[0m20:21:04  [31mCompleted with 3 errors, 0 partial successes, and 0 warnings:[0m
[0m20:21:04  
[0m20:21:04    Database Error in model dim_date (models/marts/dim_date.sql)
  relation "public.stg_weather_raw" does not exist
  LINE 10:     FROM "***"."public"."stg_weather_raw"
                    ^
  compiled code at target/run/dbt_project/models/marts/dim_date.sql
[0m20:21:04  
[0m20:21:04    Database Error in model dim_location (models/marts/dim_location.sql)
  relation "public.stg_weather_raw" does not exist
  LINE 13:     FROM "***"."public"."stg_weather_raw"
                    ^
  compiled code at target/run/dbt_project/models/marts/dim_location.sql
[0m20:21:04  
[0m20:21:04    Database Error in model dim_weather_condition (models/marts/dim_weather_condition.sql)
  relation "public.stg_weather_raw" does not exist
  LINE 11:     FROM "***"."public"."stg_weather_raw"
                    ^
  compiled code at target/run/dbt_project/models/marts/dim_weather_condition.sql
[0m20:21:04  
[0m20:21:04  Done. PASS=1 WARN=0 ERROR=3 SKIP=1 TOTAL=5

[2025-05-06T20:21:05.612+0000] {weather_etl_dag.py:21} ERROR - stderr:

[2025-05-06T20:21:05.613+0000] {taskinstance.py:441} INFO - ::group::Post task execution logs
[2025-05-06T20:21:05.614+0000] {taskinstance.py:2905} ERROR - Task failed with exception
Traceback (most recent call last):
  File "/home/airflow/.local/lib/python3.12/site-packages/airflow/models/taskinstance.py", line 465, in _execute_task
    result = _execute_callable(context=context, **execute_callable_kwargs)
             ^^^^^^^^^^^^^^^^^^^^^^^^^^^^^^^^^^^^^^^^^^^^^^^^^^^^^^^^^^^^^
  File "/home/airflow/.local/lib/python3.12/site-packages/airflow/models/taskinstance.py", line 432, in _execute_callable
    return execute_callable(context=context, **execute_callable_kwargs)
           ^^^^^^^^^^^^^^^^^^^^^^^^^^^^^^^^^^^^^^^^^^^^^^^^^^^^^^^^^^^^
  File "/home/airflow/.local/lib/python3.12/site-packages/airflow/models/baseoperator.py", line 400, in wrapper
    return func(self, *args, **kwargs)
           ^^^^^^^^^^^^^^^^^^^^^^^^^^^
  File "/home/airflow/.local/lib/python3.12/site-packages/airflow/operators/python.py", line 235, in execute
    return_value = self.execute_callable()
                   ^^^^^^^^^^^^^^^^^^^^^^^
  File "/home/airflow/.local/lib/python3.12/site-packages/airflow/operators/python.py", line 252, in execute_callable
    return self.python_callable(*self.op_args, **self.op_kwargs)
           ^^^^^^^^^^^^^^^^^^^^^^^^^^^^^^^^^^^^^^^^^^^^^^^^^^^^^
  File "/opt/airflow/dags/weather_etl_dag.py", line 10, in run_dbt
    result = subprocess.run(
             ^^^^^^^^^^^^^^^
  File "/usr/local/lib/python3.12/subprocess.py", line 571, in run
    raise CalledProcessError(retcode, process.args,
subprocess.CalledProcessError: Command '['dbt', 'run']' returned non-zero exit status 1.
[2025-05-06T20:21:05.637+0000] {taskinstance.py:1206} INFO - Marking task as FAILED. dag_id=weather_etl_dag, task_id=run_dbt, run_id=manual__2025-05-06T20:20:53.893497+00:00, execution_date=20250506T202053, start_date=20250506T202058, end_date=20250506T202105
[2025-05-06T20:21:05.653+0000] {standard_task_runner.py:110} ERROR - Failed to execute job 103 for task run_dbt (Command '['dbt', 'run']' returned non-zero exit status 1.; 1017)
[2025-05-06T20:21:05.665+0000] {local_task_job_runner.py:240} INFO - Task exited with return code 1
[2025-05-06T20:21:05.684+0000] {taskinstance.py:3498} INFO - 0 downstream tasks scheduled from follow-on schedule check
[2025-05-06T20:21:05.688+0000] {local_task_job_runner.py:222} INFO - ::endgroup::
