[2025-05-06T14:30:40.795+0000] {local_task_job_runner.py:120} INFO - ::group::Pre task execution logs
[2025-05-06T14:30:40.825+0000] {taskinstance.py:2076} INFO - Dependencies all met for dep_context=non-requeueable deps ti=<TaskInstance: weather_etl_dag.run-dbt manual__2025-05-06T14:30:36.700557+00:00 [queued]>
[2025-05-06T14:30:40.833+0000] {taskinstance.py:2076} INFO - Dependencies all met for dep_context=requeueable deps ti=<TaskInstance: weather_etl_dag.run-dbt manual__2025-05-06T14:30:36.700557+00:00 [queued]>
[2025-05-06T14:30:40.834+0000] {taskinstance.py:2306} INFO - Starting attempt 1 of 1
[2025-05-06T14:30:40.846+0000] {taskinstance.py:2330} INFO - Executing <Task(PythonOperator): run-dbt> on 2025-05-06 14:30:36.700557+00:00
[2025-05-06T14:30:40.859+0000] {standard_task_runner.py:90} INFO - Running: ['airflow', 'tasks', 'run', 'weather_etl_dag', 'run-dbt', 'manual__2025-05-06T14:30:36.700557+00:00', '--job-id', '38', '--raw', '--subdir', 'DAGS_FOLDER/weather_etl_dag.py', '--cfg-path', '/tmp/tmp7b6mqcb0']
[2025-05-06T14:30:40.862+0000] {standard_task_runner.py:91} INFO - Job 38: Subtask run-dbt
[2025-05-06T14:30:40.865+0000] {logging_mixin.py:188} WARNING - /home/airflow/.local/lib/python3.12/site-packages/airflow/task/task_runner/standard_task_runner.py:61 DeprecationWarning: This process (pid=5259) is multi-threaded, use of fork() may lead to deadlocks in the child.
[2025-05-06T14:30:40.867+0000] {standard_task_runner.py:63} INFO - Started process 5261 to run task
[2025-05-06T14:30:40.888+0000] {logging_mixin.py:188} WARNING - /home/airflow/.local/lib/python3.12/site-packages/airflow/settings.py:195 DeprecationWarning: The sql_alchemy_conn option in [core] has been moved to the sql_alchemy_conn option in [database] - the old setting has been used, but please update your config.
[2025-05-06T14:30:40.925+0000] {task_command.py:426} INFO - Running <TaskInstance: weather_etl_dag.run-dbt manual__2025-05-06T14:30:36.700557+00:00 [running]> on host 1259ec087e8d
[2025-05-06T14:30:41.009+0000] {taskinstance.py:2648} INFO - Exporting env vars: AIRFLOW_CTX_DAG_OWNER='airflow' AIRFLOW_CTX_DAG_ID='weather_etl_dag' AIRFLOW_CTX_TASK_ID='run-dbt' AIRFLOW_CTX_EXECUTION_DATE='2025-05-06T14:30:36.700557+00:00' AIRFLOW_CTX_TRY_NUMBER='1' AIRFLOW_CTX_DAG_RUN_ID='manual__2025-05-06T14:30:36.700557+00:00'
[2025-05-06T14:30:41.010+0000] {taskinstance.py:430} INFO - ::endgroup::
[2025-05-06T14:30:41.184+0000] {taskinstance.py:441} INFO - ::group::Post task execution logs
[2025-05-06T14:30:41.185+0000] {taskinstance.py:2905} ERROR - Task failed with exception
Traceback (most recent call last):
  File "/home/airflow/.local/lib/python3.12/site-packages/airflow/models/taskinstance.py", line 465, in _execute_task
    result = _execute_callable(context=context, **execute_callable_kwargs)
             ^^^^^^^^^^^^^^^^^^^^^^^^^^^^^^^^^^^^^^^^^^^^^^^^^^^^^^^^^^^^^
  File "/home/airflow/.local/lib/python3.12/site-packages/airflow/models/taskinstance.py", line 432, in _execute_callable
    return execute_callable(context=context, **execute_callable_kwargs)
           ^^^^^^^^^^^^^^^^^^^^^^^^^^^^^^^^^^^^^^^^^^^^^^^^^^^^^^^^^^^^
  File "/home/airflow/.local/lib/python3.12/site-packages/airflow/models/baseoperator.py", line 400, in wrapper
    return func(self, *args, **kwargs)
           ^^^^^^^^^^^^^^^^^^^^^^^^^^^
  File "/home/airflow/.local/lib/python3.12/site-packages/airflow/operators/python.py", line 235, in execute
    return_value = self.execute_callable()
                   ^^^^^^^^^^^^^^^^^^^^^^^
  File "/home/airflow/.local/lib/python3.12/site-packages/airflow/operators/python.py", line 252, in execute_callable
    return self.python_callable(*self.op_args, **self.op_kwargs)
           ^^^^^^^^^^^^^^^^^^^^^^^^^^^^^^^^^^^^^^^^^^^^^^^^^^^^^
  File "/opt/airflow/dags/weather_etl_dag.py", line 9, in run_dbt
    subprocess.run(['dbt', 'run'], check=True, cwd='/opt/airflow/dbt/')
  File "/usr/local/lib/python3.12/subprocess.py", line 548, in run
    with Popen(*popenargs, **kwargs) as process:
         ^^^^^^^^^^^^^^^^^^^^^^^^^^^
  File "/usr/local/lib/python3.12/subprocess.py", line 1026, in __init__
    self._execute_child(args, executable, preexec_fn, close_fds,
  File "/usr/local/lib/python3.12/subprocess.py", line 1955, in _execute_child
    raise child_exception_type(errno_num, err_msg, err_filename)
FileNotFoundError: [Errno 2] No such file or directory: '/opt/airflow/dbt/'
[2025-05-06T14:30:41.203+0000] {taskinstance.py:1206} INFO - Marking task as FAILED. dag_id=weather_etl_dag, task_id=run-dbt, run_id=manual__2025-05-06T14:30:36.700557+00:00, execution_date=20250506T143036, start_date=20250506T143040, end_date=20250506T143041
[2025-05-06T14:30:41.215+0000] {standard_task_runner.py:110} ERROR - Failed to execute job 38 for task run-dbt ([Errno 2] No such file or directory: '/opt/airflow/dbt/'; 5261)
[2025-05-06T14:30:41.243+0000] {local_task_job_runner.py:240} INFO - Task exited with return code 1
[2025-05-06T14:30:41.259+0000] {taskinstance.py:3498} INFO - 0 downstream tasks scheduled from follow-on schedule check
[2025-05-06T14:30:41.262+0000] {local_task_job_runner.py:222} INFO - ::endgroup::
